# Date

- Date 提供了解析、管理和展示时间的功能
  - 通过调用 Date 构造函数来实例化日期对象
  -  以常规函数调用它（即不加 new 操作符）将会返回一个字符串，而不是一个日期对象。
  -  Date 对象没有字面量格式

Date()    , Date.now()    ,new   Date()

-   Date 对象包含了一系列的日期时间处理的功能
  - 创建 Date 对象，例:  var now = new Date( );
-  常用操作
  - 获取当前日期时间:   toLocaleString( )
  - 获取年份、月份、日期:  getFullYear()、 getMonth()、getDate()
  - 获取小时、分钟、秒钟:   getHours()、 getMinutes()、 getSeconds()
-  Date构造器方法（静态方法）
   Date.now()
   Date.parse()
-  原型方法
   Date.prototype.get<Unit>( )   
   Date.prototype.set<Unit>( )   
   Date.prototype.toLocalTimeString( )  
   Date.prototype.toString( )  
   Date.prototype.toLocalString( )

---

# Boolean

 所有对象都是真值

Boolean({});

//true

Boolean([]);

//true

Boolean(new Boolean(false));

//true

Boolean(fuction foo(){});

//true

---

# Function

-  函数定义
  - 通过函数声明的形式来定义
  -  通过函数表达式的形式来定义
  -  通过 Function 构造函数实例化的形式来定义
-  函数调用
  - 作为函数直接调用
  -  作为对象方法调用
  -  作为构造函数调用
  -  通过 call/apply 间接调用
-  原型属性
  - Function.length
  -  Function.name
-  原型方法
  - Function.prototype.apply()
  -  Function.prototype.bind()
  -  Function.prototype.call()
  -  Function.prototype.toString()

---

# Object

- 静态方法
   Object.create()
   Object.defineProperties()
   Object.defineProperty()
   Object.getOwnPropertyDescriptor()
   Object.getOwnPropertyDescriptors()
   Object.getOwnPropertyNames()
   Object.getPrototypeOf()
   Object.setPrototypeOf()
- 原型方法
   Object.prototype.hasOwnProperty()
   Object.prototype.isPrototypeOf()
   Object.prototype.propertyIsEnumerable()
   Object.prototype.toString()
   Object.prototype.valueOf()

---

# Error

- 异常
   如果执行的语句中有一句产生错误，后面的语句不会继续执行

-  异常捕获（try catch finally）

   try 是必选的，catch 和 finally 两者至少要有其一
   如果没有 catch 块，程序将会终止

  - catch 块指定一个标识符（在上面的示例中为 e），该标识符保存抛出异常信息
  -  标识符仅在 catch 块执行时存在；catch 块执行完成后，标识符不再可用

- 对所有内置错误，catch 内的错误对象主要有两个属性：

   name ：错误名称
   message ：错误信息的文本描述
   stack(非标准)：当前调用栈：关于导致错误的嵌套调用序列，用于调试目的

- 异常抛出   throw  <expression > 
   抛出一个用户自定义的异常。
   expression 指定了异常的内容，可以为任何的 JavaScript 值

- try catch finally 嵌套

  ```
  //例1  嵌套try-catch
  
          //如果try的catch-block中发生另一个异常，则包裹该try..catch的外部try-block中的剩余代码将不会执行，因为控制流会立即跳转到外部try的catch-block。
          try {
              try {
                  throw "ErrorMessage11";
              } catch (e) {
                  throw "ErrorMessage22"; //抛出异常后将直接跳出catch，catch内后续代码不再执行
                  console.log("inside catch", e);
                  throw "ErrorMessage22";
              } finally {
                  console.log("finally 111");
              }
          } catch (e) {
              console.log("outside catch", e);
          } finally {
              console.log("finally 222");
          }
  
  
          //关于console
          console.log("logInfo");
          console.warn("warnInfo");
          console.error("errorInfo");
          console.assert(3 > 2, "有问题的话会输出这句话11111");
          console.assert(2 === "2", "有问题的话会输出这句话22222");
  
  
          //Part 2 嵌套的 try-blocks
          //1
          try {
              try {
                  throw "oops";
              } finally {
                  console.log("finally");
              }
          } catch (ex) {
              console.error("outer", ex);
          }
          // Output:
          // "finally"
          // "outer" "oops"
  
          //2
          try {
              try {
                  throw "oops";
              } catch (ex) {
                  console.error("inner", ex);
              } finally {
                  console.log("finally");
              }
          } catch (ex) {
              console.error("outer", ex);
          }
          // Output:
          // "inner" "oops"
          // "finally"
  
          //3
          try {
              try {
                  throw "oops";
              } catch (ex) {
                  console.error("inner", ex);
                  throw ex;
              } finally {
                  console.log("finally");
              }
          } catch (ex) {
              console.error("outer", ex);
          }
          // Output:
          // "inner" "oops"
          // "finally"
          // "outer" "oops"
  
          //4
          try {
              try {
                  throw "oops";
              } catch (ex) {
                  console.warn("inner", ex);
                  throw ex;
              } finally {
                  console.log("finally");
              }
          } catch (ex) {
              console.warn("outer", ex);
          }
          // Output:
          // "inner" "oops"
          // "finally"
  
          //Part33333333333333
          //思考下述两段代码的区别，思考两者调用栈CallStack的不同
          try {
              function abc(x, cb) {
                  console.log(x);
                  cb();
              }
              abc("xx", function () {
                  var arr = new Array(-1);
              });
          } catch (e) {
              console.log(e);
          }
  
          //JS的异步
          //思考这种情况是否能捕获到异常，回调函数捕获异常的问题
          try {
              function abc(x, cb) {
                  console.log(x);
                  cb();
              }
          } catch (e) {
              console.log(e);
          }
          abc("xx", function () {
              var arr = new Array(-1);
          });
  ```

  -  try catch 同步执行
     如果在预定的(scheduled)代码发生异常，如setTimeout，那么try...catch不捕获异常
    为了捕获预定执行函数内的异常，try...catch必须在函数内部

```
 try {
            setTimeout(function() {
                undefinedVariable;
            }, 1000);
        } catch(e) {
            console.log("报错信息：" + e);
        }
        
        setTimeout(function() {
            try {
                undefinedVariable; 
            } catch(e) {
                console.log("报错信息：" + e);
            }
        }, 1000);
```

---

 # Error 构造器

- new Error( [message])
-  通过 Error 的构造器可以创建一个错误对象。当运行时错误产生时，Error 的实例对象会被抛出
-  ECMAScript 定义了七种类型的错误
  -  Error
  -  ReferenceError: 引用错误
  -  TypeError: 类型错误
  -  RangeError: 范围错误
  -  SyntaxError: 语法错误
  -  EvalError: Eval错误   
  -  URIError: URI错误
- Error 是基类型，其他错误类型都继承自该类型。

- Error 构造器
   Error 对象也可用于用户自定义的异常的基础对象。
-  处理特定类型错误
   通过判断异常的类型来特定处理某一类的异常
   判断 constructor 属性，或使用 instanceof 关键字

## 案例

```
<!DOCTYPE html>
<html lang="en">

<head>
    <meta charset="UTF-8">
    <meta name="viewport" content="width=device-width, initial-scale=1.0">
    <meta http-equiv="X-UA-Compatible" content="ie=edge">
    <title>Document</title>
</head>

<body>
    <input type="text" id="inputID">
    <input type="button" onclick="Foo()" name="Test" value="测试">
    </br>
    <label>输出结果：</label>
    <label id="labelID">_______</label>
    <script>
        window.onload = function () {
            window.Foo = function () {
                var inputValue = document.getElementById("inputID").value;
                try {
                    var n = parseInt(inputValue);
                    var a = new Array(n); //定义一个数组 传3试试、再传-5试试
                    //报错之后 for循环不会执行
                    for (var i = 0; i < n; i++) {
                        a[i] = i;
                    }
                } catch (e) {
                    alert(e.name + e.message);
                    console.log("n:", n);
                    a = [];
                } finally {
                    document.getElementById("labelID").innerHTML = a + "_" + (a instanceof Array)
                }
            };
        };
    </script>
</body>

</html>
```

